<?xml version="1.0" encoding="utf-8"?>
<!-- This URDF was automatically created by SolidWorks to URDF Exporter! Originally created by Stephen Brawner (brawner@gmail.com) 
     Commit Version: 1.5.1-0-g916b5db  Build Version: 1.5.7152.31018
     For more information, please see http://wiki.ros.org/sw_urdf_exporter -->
<robot
  name="IRB120_3-58_IRC5_rev1.SLDASM">
  <link
    name="base_link">
    <inertial>
      <origin
        xyz="-0.042039 8.0122E-05 0.079638"
        rpy="0 0 0" />
      <mass
        value="6.215" />
      <inertia
        ixx="0.024621"
        ixy="2.5781E-05"
        ixz="-0.00023172"
        iyy="0.027034"
        iyz="5.6467E-06"
        izz="0.025199" />
    </inertial>
    <visual>
      <origin
        xyz="0 0 0"
        rpy="0 0 0" />
      <geometry>
        <mesh
          filename="package://IRB120_3-58_IRC5_rev1.SLDASM/meshes/base_link.STL" />
      </geometry>
      <material
        name="">
        <color
          rgba="0.79216 0.81961 0.93333 1" />
      </material>
    </visual>
    <collision>
      <origin
        xyz="0 0 0"
        rpy="0 0 0" />
      <geometry>
        <mesh
          filename="package://IRB120_3-58_IRC5_rev1.SLDASM/meshes/base_link.STL" />
      </geometry>
    </collision>
  </link>
  <link
    name="link_1">
    <inertial>
      <origin
        xyz="9.7674E-05 0.059412 0.0001193"
        rpy="0 0 0" />
      <mass
        value="3.067" />
      <inertia
        ixx="0.012269"
        ixy="6.064E-08"
        ixz="6.5514E-08"
        iyy="0.01042"
        iyz="1.0232E-05"
        izz="0.012436" />
    </inertial>
    <visual>
      <origin
        xyz="0 0 0"
        rpy="0 0 0" />
      <geometry>
        <mesh
          filename="package://IRB120_3-58_IRC5_rev1.SLDASM/meshes/link_1.STL" />
      </geometry>
      <material
        name="">
        <color
          rgba="0.79216 0.81961 0.93333 1" />
      </material>
    </visual>
    <collision>
      <origin
        xyz="0 0 0"
        rpy="0 0 0" />
      <geometry>
        <mesh
          filename="package://IRB120_3-58_IRC5_rev1.SLDASM/meshes/link_1.STL" />
      </geometry>
    </collision>
  </link>
  <joint
    name="joint_1"
    type="revolute">
    <origin
      xyz="0 0 0.29"
      rpy="0 0 0" />
    <parent
      link="base_link" />
    <child
      link="link_1" />
    <axis
      xyz="0 0 1" />
    <limit
      lower="-2.8798"
      upper="2.8798"
      effort="0"
      velocity="4.3633" />
  </joint>
  <link
    name="link_2">
    <inertial>
      <origin
        xyz="0.00077829 0.10124 0.075617"
        rpy="0 0 0" />
      <mass
        value="3.9087" />
      <inertia
        ixx="0.038125"
        ixy="-2.3951E-07"
        ixz="-6.5834E-07"
        iyy="0.0047264"
        iyz="2.4476E-05"
        izz="0.040576" />
    </inertial>
    <visual>
      <origin
        xyz="0 0 0"
        rpy="0 0 0" />
      <geometry>
        <mesh
          filename="package://IRB120_3-58_IRC5_rev1.SLDASM/meshes/link_2.STL" />
      </geometry>
      <material
        name="">
        <color
          rgba="0.8902 0.41176 0.13333 1" />
      </material>
    </visual>
    <collision>
      <origin
        xyz="0 0 0"
        rpy="0 0 0" />
      <geometry>
        <mesh
          filename="package://IRB120_3-58_IRC5_rev1.SLDASM/meshes/link_2.STL" />
      </geometry>
    </collision>
  </link>
  <joint
    name="joint_2"
    type="revolute">
    <origin
      xyz="0 0 0"
      rpy="0 -1.5708 -1.5708" />
    <parent
      link="link_1" />
    <child
      link="link_2" />
    <axis
      xyz="0 0 1" />
    <limit
      lower="-1.9199"
      upper="1.9199"
      effort="0"
      velocity="4.3633" />
  </joint>
  <link
    name="link_3">
    <inertial>
      <origin
        xyz="0.022811 0.057909 -0.031065"
        rpy="0 0 0" />
      <mass
        value="2.9435" />
      <inertia
        ixx="0.0056396"
        ixy="-0.0031991"
        ixz="-0.00012137"
        iyy="0.0109"
        iyz="-0.00011295"
        izz="0.012202" />
    </inertial>
    <visual>
      <origin
        xyz="0 0 0"
        rpy="0 0 0" />
      <geometry>
        <mesh
          filename="package://IRB120_3-58_IRC5_rev1.SLDASM/meshes/link_3.STL" />
      </geometry>
      <material
        name="">
        <color
          rgba="0.79216 0.81961 0.93333 1" />
      </material>
    </visual>
    <collision>
      <origin
        xyz="0 0 0"
        rpy="0 0 0" />
      <geometry>
        <mesh
          filename="package://IRB120_3-58_IRC5_rev1.SLDASM/meshes/link_3.STL" />
      </geometry>
    </collision>
  </link>
  <joint
    name="joint_3"
    type="revolute">
    <origin
      xyz="0 0 0.27"
      rpy="0 0 0" />
    <parent
      link="link_2" />
    <child
      link="link_3" />
    <axis
      xyz="0 0 1" />
    <limit
      lower="-1.9199"
      upper="1.2217"
      effort="0"
      velocity="4.3633" />
  </joint>
  <link
    name="link_4">
    <inertial>
      <origin
        xyz="-0.077391 0.00040577 -0.000217"
        rpy="0 0 0" />
      <mass
        value="1.3248" />
      <inertia
        ixx="0.0010405"
        ixy="5.694E-06"
        ixz="4.6804E-05"
        iyy="0.0033497"
        iyz="-8.3796E-07"
        izz="0.0038744" />
    </inertial>
    <visual>
      <origin
        xyz="0 0 0"
        rpy="0 0 0" />
      <geometry>
        <mesh
          filename="package://IRB120_3-58_IRC5_rev1.SLDASM/meshes/link_4.STL" />
      </geometry>
      <material
        name="">
        <color
          rgba="0.79216 0.81961 0.93333 1" />
      </material>
    </visual>
    <collision>
      <origin
        xyz="0 0 0"
        rpy="0 0 0" />
      <geometry>
        <mesh
          filename="package://IRB120_3-58_IRC5_rev1.SLDASM/meshes/link_4.STL" />
      </geometry>
    </collision>
  </link>
  <joint
    name="joint_4"
    type="revolute">
    <origin
      xyz="0.07 0.302 0"
      rpy="-1.5708 0 0" />
    <parent
      link="link_3" />
    <child
      link="link_4" />
    <axis
      xyz="0 0 1" />
    <limit
      lower="-2.7925"
      upper="2.7925"
      effort="0"
      velocity="5.5851" />
  </joint>
  <link
    name="link_5">
    <inertial>
      <origin
        xyz="-0.0010948 6.2217E-05 -3.6852E-05"
        rpy="0 0 0" />
      <mass
        value="0.54663" />
      <inertia
        ixx="0.00040458"
        ixy="-4.2563E-07"
        ixz="1.8447E-06"
        iyy="0.00029001"
        iyz="-8.5802E-09"
        izz="0.00036748" />
    </inertial>
    <visual>
      <origin
        xyz="0 0 0"
        rpy="0 0 0" />
      <geometry>
        <mesh
          filename="package://IRB120_3-58_IRC5_rev1.SLDASM/meshes/link_5.STL" />
      </geometry>
      <material
        name="">
        <color
          rgba="0.79216 0.81961 0.93333 1" />
      </material>
    </visual>
    <collision>
      <origin
        xyz="0 0 0"
        rpy="0 0 0" />
      <geometry>
        <mesh
          filename="package://IRB120_3-58_IRC5_rev1.SLDASM/meshes/link_5.STL" />
      </geometry>
    </collision>
  </link>
  <joint
    name="joint_5"
    type="revolute">
    <origin
      xyz="0 0 0"
      rpy="1.5708 0 0" />
    <parent
      link="link_4" />
    <child
      link="link_5" />
    <axis
      xyz="0 0 1" />
    <limit
      lower="-2.0944"
      upper="2.0944"
      effort="0"
      velocity="5.5851" />
  </joint>
  <link
    name="link_6">
    <inertial>
      <origin
        xyz="-1.3237E-06 -0.00016958 -0.0059379"
        rpy="0 0 0" />
      <mass
        value="0.013678" />
      <inertia
        ixx="1.6577E-06"
        ixy="3.0637E-12"
        ixz="-8.915E-11"
        iyy="1.6943E-06"
        iyz="-7.6625E-09"
        izz="2.9768E-06" />
    </inertial>
    <visual>
      <origin
        xyz="0 0 0"
        rpy="0 0 0" />
      <geometry>
        <mesh
          filename="package://IRB120_3-58_IRC5_rev1.SLDASM/meshes/link_6.STL" />
      </geometry>
      <material
        name="">
        <color
          rgba="0.79216 0.81961 0.93333 1" />
      </material>
    </visual>
    <collision>
      <origin
        xyz="0 0 0"
        rpy="0 0 0" />
      <geometry>
        <mesh
          filename="package://IRB120_3-58_IRC5_rev1.SLDASM/meshes/link_6.STL" />
      </geometry>
    </collision>
  </link>
  <joint
    name="joint_6"
    type="revolute">
    <origin
      xyz="0 0 0"
      rpy="-1.5708 0 0" />
    <parent
      link="link_5" />
    <child
      link="link_6" />
    <axis
      xyz="0 0 1" />
    <limit
      lower="-6.9813"
      upper="6.9813"
      effort="0"
      velocity="7.3304" />
  </joint>
  <link
    name="spoon_tool">
    <inertial>
      <origin
        xyz="-0.047629 0.0098548 2.4794E-06"
        rpy="0 0 0" />
      <mass
        value="0.014667" />
      <inertia
        ixx="6.5552E-06"
        ixy="1.4863E-05"
        ixz="-1.7336E-08"
        iyy="5.6566E-05"
        iyz="5.2813E-09"
        izz="6.0147E-05" />
    </inertial>
    <visual>
      <origin
        xyz="0 0 0"
        rpy="0 0 0" />
      <geometry>
        <mesh
          filename="package://IRB120_3-58_IRC5_rev1.SLDASM/meshes/spoon_tool.STL" />
      </geometry>
      <material
        name="">
        <color
          rgba="0.89804 0.89804 0.89804 1" />
      </material>
    </visual>
    <collision>
      <origin
        xyz="0 0 0"
        rpy="0 0 0" />
      <geometry>
        <mesh
          filename="package://IRB120_3-58_IRC5_rev1.SLDASM/meshes/spoon_tool.STL" />
      </geometry>
    </collision>
  </link>
  <joint
    name="tool_joint"
    type="fixed">
    <origin
      xyz="-0.046 0 0.2069"
      rpy="0 0 0" />
    <parent
      link="link_6" />
    <child
      link="spoon_tool" />
    <axis
      xyz="0 0 1" />
  </joint>
</robot>